Workbook

Sheet EN60
A1: MatureTable | E1: 1.005 ครบสัญญา
A2: plancode | B2: maturerate | C2: premiumrate | E2: 1.005 มรณกรรม
A3: EN60 | B3: 808 | C3: 1.01 | E3: ="INSERT INTO public.maturetable (plancode, maturerate, premiumrate) VALUES('"&A3&"', "&B3&", "&C3&");" -> INSERT INTO public.maturetable (plancode, maturerate, premiumrate) VALUES('EN60', 808, 1.01);
A5: coupontable | E5: ="INSERT INTO public.coupontable (id, returncash, ytable) VALUES('"&A7&"', "&B7&", '"&C7&"');" -> INSERT INTO public.coupontable (id, returncash, ytable) VALUES('EN60', 1, 'Y'); | I5: benefittype
A6: id | B6: returncash | C6: ytable | E6: returncash | F6: 0 | H6: ไม่มีเงินปันผล | I6: V = เอาเงินเวรคืนมาเป็นผลประโยชน์กรณีเสียชีวิต
A7: =A$3 -> EN60 | B7: 1 | C7: Y | F7: 1 | H7: มีเงินปันผล | I7: S = Max(เวรคืน, ผลประโยชน์กรณีเสียชีวิต)
E8: ytable | F8: N | H8: fix ปี ไม่ search ด้วยอายุ | I8: A = Max(เวรคืน, ผลประโยชน์กรณีเสียชีวิต, 1.005เท่าของเบี้ยที่จ่าย)
F9: Y | H9: ต้องส่งอายุไป search ด้วย | I9: อื่นๆ = แสดงผลประโยชน์กรณีเสียชีวิต

Sheet เงินคืน EN60(age 0-10)
A1: MatureTable | E1: 1.005 ครบสัญญา
A2: plancode | B2: maturerate | C2: premiumrate | E2: 1.005 มรณกรรม
A3: ='EN60'!A$3 -> EN60 | B3: ='EN60'!B$3 -> 808 | C3: ='EN60'!C$3 -> 1.01 | E3: ="INSERT INTO public.maturetable (plancode, maturerate, premiumrate) VALUES('"&A3&"', "&B3&", "&C3&");" -> INSERT INTO public.maturetable (plancode, maturerate, premiumrate) VALUES('EN60', 808, 1.01);
A5: coupontable | E5: ="INSERT INTO public.coupontable (id, returncash, ytable) VALUES('"&A7&"', "&B7&", '"&C7&"');" -> INSERT INTO public.coupontable (id, returncash, ytable) VALUES('EN60', 1, 'Y'); | I5: benefittype
A6: id | B6: returncash | C6: ytable | E6: returncash | F6: 0 | G6: ไม่มีเงินปันผล | I6: V = เอาเงินเวรคืนมาเป็นผลประโยชน์กรณีเสียชีวิต
A7: =A$3 -> EN60 | B7: ='EN60'!B$7 -> 1 | C7: ='EN60'!C$7 -> Y | F7: 1 | G7: มีเงินปันผล | I7: S = Max(เวรคืน, ผลประโยชน์กรณีเสียชีวิต)
E8: ytable | F8: N | G8: fix ปี ไม่ search ด้วยอายุ | I8: A = Max(เวรคืน, ผลประโยชน์กรณีเสียชีวิต, 1.005เท่าของเบี้ยที่จ่าย)
F9: Y | G9: ต้องส่งอายุไป search ด้วย | I9: อื่นๆ = แสดงผลประโยชน์กรณีเสียชีวิต
A10: coupon
A11: plancode | B11: age | C11: year | D11: couponrate | E11: benefittype | F11: benefitrate | G11: premiumrate | I11: ="[{""plancode"":"""&A12&""",""returncash"":"""&B$7&""",""ytable"":"""&C$7&""",""maturerate"":"""&B$3&""",""maturepmrate"":"""&C$3&""",""coupon"":[" -> [{"plancode":"EN60","returncash":"1","ytable":"Y","maturerate":"808","maturepmrate":"1.01","coupon":[
A12: ='EN60'!A$3 -> EN60 | B12: 0 | C12: 1 | D12: =IF(C12+B12=80,0,8) -> 8 | E12: A | F12: =IF(C12>7, 800, C12*100) -> 100 | G12: ='EN60'!C$3 -> 1.01 | H12: ="INSERT INTO public.coupon ("&A$11&", "&B$11&", """&C$11&""", "&D$11&", "&E$11&", "&F$11&", "&G$11&") VALUES('"&A12&"', "&B12&", "&C12&", "&D12&", '"&E12&"',"&F12&", "&G12&");" -> INSERT INTO public.coupon (plancode, age, "year", couponrate, benefittype, benefitrate, premiumrate) VALUES('EN60', 0, 1, 8, 'A',100, 1.01); | I12: ="{""age"":"""&B12&""", ""year"":"""&C12&""", ""couponrate"":"""&D12&""", ""benefittype"":"""&E12&""", ""benefitrate"":"""&F12&""", """&G$11&""":"""&G12&"""}" -> {"age":"0", "year":"1", "couponrate":"8", "benefittype":"A", "benefitrate":"100", "premiumrate":"1.01"} | J12: =IF(OR(I13="]", I12="[", I12="]"), "", ",") -> ,
A13: ='EN60'!A$3 -> EN60 | B13: =B12 -> 0 | C13: =C12+1 -> 2 | D13: =IF(C13+B13=80,0,8) -> 8 | E13: A | F13: =IF(C13>7, 800, C13*100) -> 200 | G13: =G12 -> 1.01 | H13: ="INSERT INTO public.coupon ("&A$11&", "&B$11&", """&C$11&""", "&D$11&", "&E$11&", "&F$11&", "&G$11&") VALUES('"&A13&"', "&B13&", "&C13&", "&D13&", '"&E13&"',"&F13&", "&G13&");" -> INSERT INTO public.coupon (plancode, age, "year", couponrate, benefittype, benefitrate, premiumrate) VALUES('EN60', 0, 2, 8, 'A',200, 1.01); | I13: ="{""age"":"""&B13&""", ""year"":"""&C13&""", ""couponrate"":"""&D13&""", ""benefittype"":"""&E13&""", ""benefitrate"":"""&F13&""", """&G$11&""":"""&G13&"""}" -> {"age":"0", "year":"2", "couponrate":"8", "benefittype":"A", "benefitrate":"200", "premiumrate":"1.01"} | J13: =IF(OR(I14="]", I13="[", I13="]"), "", ",") -> ,
A14: ='EN60'!A$3 -> EN60 | B14: =B13 -> 0 | C14: =C13+1 -> 3 | D14: =IF(C14+B14=80,0,8) -> 8 | E14: A | F14: =IF(C14>7, 800, C14*100) -> 300 | G14: =G13 -> 1.01 | H14: ="INSERT INTO public.coupon ("&A$11&", "&B$11&", """&C$11&""", "&D$11&", "&E$11&", "&F$11&", "&G$11&") VALUES('"&A14&"', "&B14&", "&C14&", "&D14&", '"&E14&"',"&F14&", "&G14&");" -> INSERT INTO public.coupon (plancode, age, "year", couponrate, benefittype, benefitrate, premiumrate) VALUES('EN60', 0, 3, 8, 'A',300, 1.01); | I14: ="{""age"":"""&B14&""", ""year"":"""&C14&""", ""couponrate"":"""&D14&""", ""benefittype"":"""&E14&""", ""benefitrate"":"""&F14&""", """&G$11&""":"""&G14&"""}" -> {"age":"0", "year":"3", "couponrate":"8", "benefittype":"A", "benefitrate":"300", "premiumrate":"1.01"} | J14: =IF(OR(I15="]", I14="[", I14="]"), "", ",") -> ,
A15: ='EN60'!A$3 -> EN60 | B15: =B14 -> 0 | C15: =C14+1 -> 4 | D15: =IF(C15+B15=80,0,8) -> 8 | E15: A | F15: =IF(C15>7, 800, C15*100) -> 400 | G15: =G14 -> 1.01 | H15: ="INSERT INTO public.coupon ("&A$11&", "&B$11&", """&C$11&""", "&D$11&", "&E$11&", "&F$11&", "&G$11&") VALUES('"&A15&"', "&B15&", "&C15&", "&D15&", '"&E15&"',"&F15&", "&G15&");" -> INSERT INTO public.coupon (plancode, age, "year", couponrate, benefittype, benefitrate, premiumrate) VALUES('EN60', 0, 4, 8, 'A',400, 1.01); | I15: ="{""age"":"""&B15&""", ""year"":"""&C15&""", ""couponrate"":"""&D15&""", ""benefittype"":"""&E15&""", ""benefitrate"":"""&F15&""", """&G$11&""":"""&G15&"""}" -> {"age":"0", "year":"4", "couponrate":"8", "benefittype":"A", "benefitrate":"400", "premiumrate":"1.01"} | J15: =IF(OR(I16="]", I15="[", I15="]"), "", ",") -> ,
A16: ='EN60'!A$3 -> EN60 | B16: =B15 -> 0 | C16: =C15+1 -> 5 | D16: =IF(C16+B16=80,0,8) -> 8 | E16: A | F16: =IF(C16>7, 800, C16*100) -> 500 | G16: =G15 -> 1.01 | H16: ="INSERT INTO public.coupon ("&A$11&", "&B$11&", """&C$11&""", "&D$11&", "&E$11&", "&F$11&", "&G$11&") VALUES('"&A16&"', "&B16&", "&C16&", "&D16&", '"&E16&"',"&F16&", "&G16&");" -> INSERT INTO public.coupon (plancode, age, "year", couponrate, benefittype, benefitrate, premiumrate) VALUES('EN60', 0, 5, 8, 'A',500, 1.01); | I16: ="{""age"":"""&B16&""", ""year"":"""&C16&""", ""couponrate"":"""&D16&""", ""benefittype"":"""&E16&""", ""benefitrate"":"""&F16&""", """&G$11&""":"""&G16&"""}" -> {"age":"0", "year":"5", "couponrate":"8", "benefittype":"A", "benefitrate":"500", "premiumrate":"1.01"} | J16: =IF(OR(I17="]", I16="[", I16="]"), "", ",") -> ,
A17: ='EN60'!A$3 -> EN60 | B17: =B16 -> 0 | C17: =C16+1 -> 6 | D17: =IF(C17+B17=80,0,8) -> 8 | E17: A | F17: =IF(C17>7, 800, C17*100) -> 600 | G17: =G16 -> 1.01 | H17: ="INSERT INTO public.coupon ("&A$11&", "&B$11&", """&C$11&""", "&D$11&", "&E$11&", "&F$11&", "&G$11&") VALUES('"&A17&"', "&B17&", "&C17&", "&D17&", '"&E17&"',"&F17&", "&G17&");" -> INSERT INTO public.coupon (plancode, age, "year", couponrate, benefittype, benefitrate, premiumrate) VALUES('EN60', 0, 6, 8, 'A',600, 1.01); | I17: ="{""age"":"""&B17&""", ""year"":"""&C17&""", ""couponrate"":"""&D17&""", ""benefittype"":"""&E17&""", ""benefitrate"":"""&F17&""", """&G$11&""":"""&G17&"""}" -> {"age":"0", "year":"6", "couponrate":"8", "benefittype":"A", "benefitrate":"600", "premiumrate":"1.01"} | J17: =IF(OR(I18="]", I17="[", I17="]"), "", ",") -> ,
A18: ='EN60'!A$3 -> EN60 | B18: =B17 -> 0 | C18: =C17+1 -> 7 | D18: =IF(C18+B18=80,0,8) -> 8 | E18: A | F18: =IF(C18>7, 800, C18*100) -> 700 | G18: =G17 -> 1.01 | H18: ="INSERT INTO public.coupon ("&A$11&", "&B$11&", """&C$11&""", "&D$11&", "&E$11&", "&F$11&", "&G$11&") VALUES('"&A18&"', "&B18&", "&C18&", "&D18&", '"&E18&"',"&F18&", "&G18&");" -> INSERT INTO public.coupon (plancode, age, "year", couponrate, benefittype, benefitrate, premiumrate) VALUES('EN60', 0, 7, 8, 'A',700, 1.01); | I18: ="{""age"":"""&B18&""", ""year"":"""&C18&""", ""couponrate"":"""&D18&""", ""benefittype"":"""&E18&""", ""benefitrate"":"""&F18&""", """&G$11&""":"""&G18&"""}" -> {"age":"0", "year":"7", "couponrate":"8", "benefittype":"A", "benefitrate":"700", "premiumrate":"1.01"} | J18: =IF(OR(I19="]", I18="[", I18="]"), "", ",") -> ,
A19: ='EN60'!A$3 -> EN60 | B19: =B18 -> 0 | C19: =C18+1 -> 8 | D19: =IF(C19+B19=80,0,8) -> 8 | E19: A | F19: =IF(C19>7, 800, C19*100) -> 800 | G19: =G18 -> 1.01 | H19: ="INSERT INTO public.coupon ("&A$11&", "&B$11&", """&C$11&""", "&D$11&", "&E$11&", "&F$11&", "&G$11&") VALUES('"&A19&"', "&B19&", "&C19&", "&D19&", '"&E19&"',"&F19&", "&G19&");" -> INSERT INTO public.coupon (plancode, age, "year", couponrate, benefittype, benefitrate, premiumrate) VALUES('EN60', 0, 8, 8, 'A',800, 1.01); | I19: ="{""age"":"""&B19&""", ""year"":"""&C19&""", ""couponrate"":"""&D19&""", ""benefittype"":"""&E19&""", ""benefitrate"":"""&F19&""", """&G$11&""":"""&G19&"""}" -> {"age":"0", "year":"8", "couponrate":"8", "benefittype":"A", "benefitrate":"800", "premiumrate":"1.01"} | J19: =IF(OR(I20="]", I19="[", I19="]"), "", ",") -> ,
A20: ='EN60'!A$3 -> EN60 | B20: =B19 -> 0 | C20: =C19+1 -> 9 | D20: =IF(C20+B20=80,0,8) -> 8 | E20: A | F20: =IF(C20>7, 800, C20*100) -> 800 | G20: =G19 -> 1.01 | H20: ="INSERT INTO public.coupon ("&A$11&", "&B$11&", """&C$11&""", "&D$11&", "&E$11&", "&F$11&", "&G$11&") VALUES('"&A20&"', "&B20&", "&C20&", "&D20&", '"&E20&"',"&F20&", "&G20&");" -> INSERT INTO public.coupon (plancode, age, "year", couponrate, benefittype, benefitrate, premiumrate) VALUES('EN60', 0, 9, 8, 'A',800, 1.01); | I20: ="{""age"":"""&B20&""", ""year"":"""&C20&""", ""couponrate"":"""&D20&""", ""benefittype"":"""&E20&""", ""benefitrate"":"""&F20&""", """&G$11&""":"""&G20&"""}" -> {"age":"0", "year":"9", "couponrate":"8", "benefittype":"A", "benefitrate":"800", "premiumrate":"1.01"} | J20: =IF(OR(I21="]", I20="[", I20="]"), "", ",") -> ,
A21: ='EN60'!A$3 -> EN60 | B21: =B20 -> 0 | C21: =C20+1 -> 10 | D21: =IF(C21+B21=80,0,8) -> 8 | E21: A | F21: =IF(C21>7, 800, C21*100) -> 800 | G21: =G20 -> 1.01 | H21: ="INSERT INTO public.coupon ("&A$11&", "&B$11&", """&C$11&""", "&D$11&", "&E$11&", "&F$11&", "&G$11&") VALUES('"&A21&"', "&B21&", "&C21&", "&D21&", '"&E21&"',"&F21&", "&G21&");" -> INSERT INTO public.coupon (plancode, age, "year", couponrate, benefittype, benefitrate, premiumrate) VALUES('EN60', 0, 10, 8, 'A',800, 1.01); | I21: ="{""age"":"""&B21&""", ""year"":"""&C21&""", ""couponrate"":"""&D21&""", ""benefittype"":"""&E21&""", ""benefitrate"":"""&F21&""", """&G$11&""":"""&G21&"""}" -> {"age":"0", "year":"10", "couponrate":"8", "benefittype":"A", "benefitrate":"800", "premiumrate":"1.01"} | J21: =IF(OR(I22="]", I21="[", I21="]"), "", ",") -> ,
A22: ='EN60'!A$3 -> EN60 | B22: =B21 -> 0 | C22: =C21+1 -> 11 | D22: =IF(C22+B22=80,0,8) -> 8 | E22: A | F22: =IF(C22>7, 800, C22*100) -> 800 | G22: =G21 -> 1.01 | H22: ="INSERT INTO public.coupon ("&A$11&", "&B$11&", """&C$11&""", "&D$11&", "&E$11&", "&F$11&", "&G$11&") VALUES('"&A22&"', "&B22&", "&C22&", "&D22&", '"&E22&"',"&F22&", "&G22&");" -> INSERT INTO public.coupon (plancode, age, "year", couponrate, benefittype, benefitrate, premiumrate) VALUES('EN60', 0, 11, 8, 'A',800, 1.01); | I22: ="{""age"":"""&B22&""", ""year"":"""&C22&""", ""couponrate"":"""&D22&""", ""benefittype"":"""&E22&""", ""benefitrate"":"""&F22&""", """&G$11&""":"""&G22&"""}" -> {"age":"0", "year":"11", "couponrate":"8", "benefittype":"A", "benefitrate":"800", "premiumrate":"1.01"} | J22: =IF(OR(I23="]", I22="[", I22="]"), "", ",") -> ,
A23: ='EN60'!A$3 -> EN60 | B23: =B22 -> 0 | C23: =C22+1 -> 12 | D23: =IF(C23+B23=80,0,8) -> 8 | E23: A | F23: =IF(C23>7, 800, C23*100) -> 800 | G23: =G22 -> 1.01 | H23: ="INSERT INTO public.coupon ("&A$11&", "&B$11&", """&C$11&""", "&D$11&", "&E$11&", "&F$11&", "&G$11&") VALUES('"&A23&"', "&B23&", "&C23&", "&D23&", '"&E23&"',"&F23&", "&G23&");" -> INSERT INTO public.coupon (plancode, age, "year", couponrate, benefittype, benefitrate, premiumrate) VALUES('EN60', 0, 12, 8, 'A',800, 1.01); | I23: ="{""age"":"""&B23&""", ""year"":"""&C23&""", ""couponrate"":"""&D23&""", ""benefittype"":"""&E23&""", ""benefitrate"":"""&F23&""", """&G$11&""":"""&G23&"""}" -> {"age":"0", "year":"12", "couponrate":"8", "benefittype":"A", "benefitrate":"800", "premiumrate":"1.01"} | J23: =IF(OR(I24="]", I23="[", I23="]"), "", ",") -> ,
A24: ='EN60'!A$3 -> EN60 | B24: =B23 -> 0 | C24: =C23+1 -> 13 | D24: =IF(C24+B24=80,0,8) -> 8 | E24: A | F24: =IF(C24>7, 800, C24*100) -> 800 | G24: =G23 -> 1.01 | H24: ="INSERT INTO public.coupon ("&A$11&", "&B$11&", """&C$11&""", "&D$11&", "&E$11&", "&F$11&", "&G$11&") VALUES('"&A24&"', "&B24&", "&C24&", "&D24&", '"&E24&"',"&F24&", "&G24&");" -> INSERT INTO public.coupon (plancode, age, "year", couponrate, benefittype, benefitrate, premiumrate) VALUES('EN60', 0, 13, 8, 'A',800, 1.01); | I24: ="{""age"":"""&B24&""", ""year"":"""&C24&""", ""couponrate"":"""&D24&""", ""benefittype"":"""&E24&""", ""benefitrate"":"""&F24&""", """&G$11&""":"""&G24&"""}" -> {"age":"0", "year":"13", "couponrate":"8", "benefittype":"A", "benefitrate":"800", "premiumrate":"1.01"} | J24: =IF(OR(I25="]", I24="[", I24="]"), "", ",") -> ,
... A91: ='EN60'!A$3 -> EN60 | B91: =B90 -> 0 | C91: =C90+1 -> 80 | D91: =IF(C91+B91=80,0,8) -> 0 | E91: A | F91: =IF(C91>7, 800, C91*100) -> 800 | G91: =G90 -> 1.01 | H91: ="INSERT INTO public.coupon ("&A$11&", "&B$11&", """&C$11&""", "&D$11&", "&E$11&", "&F$11&", "&G$11&") VALUES('"&A91&"', "&B91&", "&C91&", "&D91&", '"&E91&"',"&F91&", "&G91&");" -> INSERT INTO public.coupon (plancode, age, "year", couponrate, benefittype, benefitrate, premiumrate) VALUES('EN60', 0, 80, 0, 'A',800, 1.01); | I91: ="{""age"":"""&B91&""", ""year"":"""&C91&""", ""couponrate"":"""&D91&""", ""benefittype"":"""&E91&""", ""benefitrate"":"""&F91&""", """&G$11&""":"""&G91&"""}" -> {"age":"0", "year":"80", "couponrate":"0", "benefittype":"A", "benefitrate":"800", "premiumrate":"1.01"} | J91: =IF(OR(I92="]", I91="[", I91="]"), "", ",") -> ,
I92: ]}]
A93: plancode | B93: age | C93: year | D93: couponrate | E93: benefittype | F93: benefitrate | G93: premiumrate | I93: ="[{""plancode"":"""&A94&""",""returncash"":"""&B$7&""",""ytable"":"""&C$7&""",""maturerate"":"""&B$3&""",""maturepmrate"":"""&C$3&""",""coupon"":[" -> [{"plancode":"EN60","returncash":"1","ytable":"Y","maturerate":"808","maturepmrate":"1.01","coupon":[
A94: ='EN60'!A$3 -> EN60 | B94: 1 | C94: 1 | D94: =IF(C94+B94=80,0,8) -> 8 | E94: A | F94: =IF(C94>7, 800, C94*100) -> 100 | G94: ='EN60'!C$3 -> 1.01 | H94: ="INSERT INTO public.coupon ("&A$11&", "&B$11&", """&C$11&""", "&D$11&", "&E$11&", "&F$11&", "&G$11&") VALUES('"&A94&"', "&B94&", "&C94&", "&D94&", '"&E94&"',"&F94&", "&G94&");" -> INSERT INTO public.coupon (plancode, age, "year", couponrate, benefittype, benefitrate, premiumrate) VALUES('EN60', 1, 1, 8, 'A',100, 1.01); | I94: ="{""age"":"""&B94&""", ""year"":"""&C94&""", ""couponrate"":"""&D94&""", ""benefittype"":"""&E94&""", ""benefitrate"":"""&F94&""", """&G$11&""":"""&G94&"""}" -> {"age":"1", "year":"1", "couponrate":"8", "benefittype":"A", "benefitrate":"100", "premiumrate":"1.01"} | J94: =IF(OR(I95="]", I94="[", I94="]"), "", ",") -> ,
A95: ='EN60'!A$3 -> EN60 | B95: =B94 -> 1 | C95: =C94+1 -> 2 | D95: =IF(C95+B95=80,0,8) -> 8 | E95: A | F95: =IF(C95>7, 800, C95*100) -> 200 | G95: =G94 -> 1.01 | H95: ="INSERT INTO public.coupon ("&A$11&", "&B$11&", """&C$11&""", "&D$11&", "&E$11&", "&F$11&", "&G$11&") VALUES('"&A95&"', "&B95&", "&C95&", "&D95&", '"&E95&"',"&F95&", "&G95&");" -> INSERT INTO public.coupon (plancode, age, "year", couponrate, benefittype, benefitrate, premiumrate) VALUES('EN60', 1, 2, 8, 'A',200, 1.01); | I95: ="{""age"":"""&B95&""", ""year"":"""&C95&""", ""couponrate"":"""&D95&""", ""benefittype"":"""&E95&""", ""benefitrate"":"""&F95&""", """&G$11&""":"""&G95&"""}" -> {"age":"1", "year":"2", "couponrate":"8", "benefittype":"A", "benefitrate":"200", "premiumrate":"1.01"} | J95: =IF(OR(I96="]", I95="[", I95="]"), "", ",") -> ,
A96: ='EN60'!A$3 -> EN60 | B96: =B95 -> 1 | C96: =C95+1 -> 3 | D96: =IF(C96+B96=80,0,8) -> 8 | E96: A | F96: =IF(C96>7, 800, C96*100) -> 300 | G96: =G95 -> 1.01 | H96: ="INSERT INTO public.coupon ("&A$11&", "&B$11&", """&C$11&""", "&D$11&", "&E$11&", "&F$11&", "&G$11&") VALUES('"&A96&"', "&B96&", "&C96&", "&D96&", '"&E96&"',"&F96&", "&G96&");" -> INSERT INTO public.coupon (plancode, age, "year", couponrate, benefittype, benefitrate, premiumrate) VALUES('EN60', 1, 3, 8, 'A',300, 1.01); | I96: ="{""age"":"""&B96&""", ""year"":"""&C96&""", ""couponrate"":"""&D96&""", ""benefittype"":"""&E96&""", ""benefitrate"":"""&F96&""", """&G$11&""":"""&G96&"""}" -> {"age":"1", "year":"3", "couponrate":"8", "benefittype":"A", "benefitrate":"300", "premiumrate":"1.01"} | J96: =IF(OR(I97="]", I96="[", I96="]"), "", ",") -> ,
A97: ='EN60'!A$3 -> EN60 | B97: =B96 -> 1 | C97: =C96+1 -> 4 | D97: =IF(C97+B97=80,0,8) -> 8 | E97: A | F97: =IF(C97>7, 800, C97*100) -> 400 | G97: =G96 -> 1.01 | H97: ="INSERT INTO public.coupon ("&A$11&", "&B$11&", """&C$11&""", "&D$11&", "&E$11&", "&F$11&", "&G$11&") VALUES('"&A97&"', "&B97&", "&C97&", "&D97&", '"&E97&"',"&F97&", "&G97&");" -> INSERT INTO public.coupon (plancode, age, "year", couponrate, benefittype, benefitrate, premiumrate) VALUES('EN60', 1, 4, 8, 'A',400, 1.01); | I97: ="{""age"":"""&B97&""", ""year"":"""&C97&""", ""couponrate"":"""&D97&""", ""benefittype"":"""&E97&""", ""benefitrate"":"""&F97&""", """&G$11&""":"""&G97&"""}" -> {"age":"1", "year":"4", "couponrate":"8", "benefittype":"A", "benefitrate":"400", "premiumrate":"1.01"} | J97: =IF(OR(I98="]", I97="[", I97="]"), "", ",") -> ,
A98: ='EN60'!A$3 -> EN60 | B98: =B97 -> 1 | C98: =C97+1 -> 5 | D98: =IF(C98+B98=80,0,8) -> 8 | E98: A | F98: =IF(C98>7, 800, C98*100) -> 500 | G98: =G97 -> 1.01 | H98: ="INSERT INTO public.coupon ("&A$11&", "&B$11&", """&C$11&""", "&D$11&", "&E$11&", "&F$11&", "&G$11&") VALUES('"&A98&"', "&B98&", "&C98&", "&D98&", '"&E98&"',"&F98&", "&G98&");" -> INSERT INTO public.coupon (plancode, age, "year", couponrate, benefittype, benefitrate, premiumrate) VALUES('EN60', 1, 5, 8, 'A',500, 1.01); | I98: ="{""age"":"""&B98&""", ""year"":"""&C98&""", ""couponrate"":"""&D98&""", ""benefittype"":"""&E98&""", ""benefitrate"":"""&F98&""", """&G$11&""":"""&G98&"""}" -> {"age":"1", "year":"5", "couponrate":"8", "benefittype":"A", "benefitrate":"500", "premiumrate":"1.01"} | J98: =IF(OR(I99="]", I98="[", I98="]"), "", ",") -> ,
A99: ='EN60'!A$3 -> EN60 | B99: =B98 -> 1 | C99: =C98+1 -> 6 | D99: =IF(C99+B99=80,0,8) -> 8 | E99: A | F99: =IF(C99>7, 800, C99*100) -> 600 | G99: =G98 -> 1.01 | H99: ="INSERT INTO public.coupon ("&A$11&", "&B$11&", """&C$11&""", "&D$11&", "&E$11&", "&F$11&", "&G$11&") VALUES('"&A99&"', "&B99&", "&C99&", "&D99&", '"&E99&"',"&F99&", "&G99&");" -> INSERT INTO public.coupon (plancode, age, "year", couponrate, benefittype, benefitrate, premiumrate) VALUES('EN60', 1, 6, 8, 'A',600, 1.01); | I99: ="{""age"":"""&B99&""", ""year"":"""&C99&""", ""couponrate"":"""&D99&""", ""benefittype"":"""&E99&""", ""benefitrate"":"""&F99&""", """&G$11&""":"""&G99&"""}" -> {"age":"1", "year":"6", "couponrate":"8", "benefittype":"A", "benefitrate":"600", "premiumrate":"1.01"} | J99: =IF(OR(I100="]", I99="[", I99="]"), "", ",") -> ,
A100: ='EN60'!A$3 -> EN60 | B100: =B99 -> 1 | C100: =C99+1 -> 7 | D100: =IF(C100+B100=80,0,8) -> 8 | E100: A | F100: =IF(C100>7, 800, C100*100) -> 700 | G100: =G99 -> 1.01 | H100: ="INSERT INTO public.coupon ("&A$11&", "&B$11&", """&C$11&""", "&D$11&", "&E$11&", "&F$11&", "&G$11&") VALUES('"&A100&"', "&B100&", "&C100&", "&D100&", '"&E100&"',"&F100&", "&G100&");" -> INSERT INTO public.coupon (plancode, age, "year", couponrate, benefittype, benefitrate, premiumrate) VALUES('EN60', 1, 7, 8, 'A',700, 1.01); | I100: ="{""age"":"""&B100&""", ""year"":"""&C100&""", ""couponrate"":"""&D100&""", ""benefittype"":"""&E100&""", ""benefitrate"":"""&F100&""", """&G$11&""":"""&G100&"""}" -> {"age":"1", "year":"7", "couponrate":"8", "benefittype":"A", "benefitrate":"700", "premiumrate":"1.01"} | J100: =IF(OR(I101="]", I100="[", I100="]"), "", ",") -> ,
A101: ='EN60'!A$3 -> EN60 | B101: =B100 -> 1 | C101: =C100+1 -> 8 | D101: =IF(C101+B101=80,0,8) -> 8 | E101: A | F101: =IF(C101>7, 800, C101*100) -> 800 | G101: =G100 -> 1.01 | H101: ="INSERT INTO public.coupon ("&A$11&", "&B$11&", """&C$11&""", "&D$11&", "&E$11&", "&F$11&", "&G$11&") VALUES('"&A101&"', "&B101&", "&C101&", "&D101&", '"&E101&"',"&F101&", "&G101&");" -> INSERT INTO public.coupon (plancode, age, "year", couponrate, benefittype, benefitrate, premiumrate) VALUES('EN60', 1, 8, 8, 'A',800, 1.01); | I101: ="{""age"":"""&B101&""", ""year"":"""&C101&""", ""couponrate"":"""&D101&""", ""benefittype"":"""&E101&""", ""benefitrate"":"""&F101&""", """&G$11&""":"""&G101&"""}" -> {"age":"1", "year":"8", "couponrate":"8", "benefittype":"A", "benefitrate":"800", "premiumrate":"1.01"} | J101: =IF(OR(I102="]", I101="[", I101="]"), "", ",") -> ,
A102: ='EN60'!A$3 -> EN60 | B102: =B101 -> 1 | C102: =C101+1 -> 9 | D102: =IF(C102+B102=80,0,8) -> 8 | E102: A | F102: =IF(C102>7, 800, C102*100) -> 800 | G102: =G101 -> 1.01 | H102: ="INSERT INTO public.coupon ("&A$11&", "&B$11&", """&C$11&""", "&D$11&", "&E$11&", "&F$11&", "&G$11&") VALUES('"&A102&"', "&B102&", "&C102&", "&D102&", '"&E102&"',"&F102&", "&G102&");" -> INSERT INTO public.coupon (plancode, age, "year", couponrate, benefittype, benefitrate, premiumrate) VALUES('EN60', 1, 9, 8, 'A',800, 1.01); | I102: ="{""age"":"""&B102&""", ""year"":"""&C102&""", ""couponrate"":"""&D102&""", ""benefittype"":"""&E102&""", ""benefitrate"":"""&F102&""", """&G$11&""":"""&G102&"""}" -> {"age":"1", "year":"9", "couponrate":"8", "benefittype":"A", "benefitrate":"800", "premiumrate":"1.01"} | J102: =IF(OR(I103="]", I102="[", I102="]"), "", ",") -> ,
A103: ='EN60'!A$3 -> EN60 | B103: =B102 -> 1 | C103: =C102+1 -> 10 | D103: =IF(C103+B103=80,0,8) -> 8 | E103: A | F103: =IF(C103>7, 800, C103*100) -> 800 | G103: =G102 -> 1.01 | H103: ="INSERT INTO public.coupon ("&A$11&", "&B$11&", """&C$11&""", "&D$11&", "&E$11&", "&F$11&", "&G$11&") VALUES('"&A103&"', "&B103&", "&C103&", "&D103&", '"&E103&"',"&F103&", "&G103&");" -> INSERT INTO public.coupon (plancode, age, "year", couponrate, benefittype, benefitrate, premiumrate) VALUES('EN60', 1, 10, 8, 'A',800, 1.01); | I103: ="{""age"":"""&B103&""", ""year"":"""&C103&""", ""couponrate"":"""&D103&""", ""benefittype"":"""&E103&""", ""benefitrate"":"""&F103&""", """&G$11&""":"""&G103&"""}" -> {"age":"1", "year":"10", "couponrate":"8", "benefittype":"A", "benefitrate":"800", "premiumrate":"1.01"} | J103: =IF(OR(I104="]", I103="[", I103="]"), "", ",") -> ,
A104: ='EN60'!A$3 -> EN60 | B104: =B103 -> 1 | C104: =C103+1 -> 11 | D104: =IF(C104+B104=80,0,8) -> 8 | E104: A | F104: =IF(C104>7, 800, C104*100) -> 800 | G104: =G103 -> 1.01 | H104: ="INSERT INTO public.coupon ("&A$11&", "&B$11&", """&C$11&""", "&D$11&", "&E$11&", "&F$11&", "&G$11&") VALUES('"&A104&"', "&B104&", "&C104&", "&D104&", '"&E104&"',"&F104&", "&G104&");" -> INSERT INTO public.coupon (plancode, age, "year", couponrate, benefittype, benefitrate, premiumrate) VALUES('EN60', 1, 11, 8, 'A',800, 1.01); | I104: ="{""age"":"""&B104&""", ""year"":"""&C104&""", ""couponrate"":"""&D104&""", ""benefittype"":"""&E104&""", ""benefitrate"":"""&F104&""", """&G$11&""":"""&G104&"""}" -> {"age":"1", "year":"11", "couponrate":"8", "benefittype":"A", "benefitrate":"800", "premiumrate":"1.01"} | J104: =IF(OR(I105="]", I104="[", I104="]"), "", ",") -> ,
A105: ='EN60'!A$3 -> EN60 | B105: =B104 -> 1 | C105: =C104+1 -> 12 | D105: =IF(C105+B105=80,0,8) -> 8 | E105: A | F105: =IF(C105>7, 800, C105*100) -> 800 | G105: =G104 -> 1.01 | H105: ="INSERT INTO public.coupon ("&A$11&", "&B$11&", """&C$11&""", "&D$11&", "&E$11&", "&F$11&", "&G$11&") VALUES('"&A105&"', "&B105&", "&C105&", "&D105&", '"&E105&"',"&F105&", "&G105&");" -> INSERT INTO public.coupon (plancode, age, "year", couponrate, benefittype, benefitrate, premiumrate) VALUES('EN60', 1, 12, 8, 'A',800, 1.01); | I105: ="{""age"":"""&B105&""", ""year"":"""&C105&""", ""couponrate"":"""&D105&""", ""benefittype"":"""&E105&""", ""benefitrate"":"""&F105&""", """&G$11&""":"""&G105&"""}" -> {"age":"1", "year":"12", "couponrate":"8", "benefittype":"A", "benefitrate":"800", "premiumrate":"1.01"} | J105: =IF(OR(I106="]", I105="[", I105="]"), "", ",") -> ,
A106: ='EN60'!A$3 -> EN60 | B106: =B105 -> 1 | C106: =C105+1 -> 13 | D106: =IF(C106+B106=80,0,8) -> 8 | E106: A | F106: =IF(C106>7, 800, C106*100) -> 800 | G106: =G105 -> 1.01 | H106: ="INSERT INTO public.coupon ("&A$11&", "&B$11&", """&C$11&""", "&D$11&", "&E$11&", "&F$11&", "&G$11&") VALUES('"&A106&"', "&B106&", "&C106&", "&D106&", '"&E106&"',"&F106&", "&G106&");" -> INSERT INTO public.coupon (plancode, age, "year", couponrate, benefittype, benefitrate, premiumrate) VALUES('EN60', 1, 13, 8, 'A',800, 1.01); | I106: ="{""age"":"""&B106&""", ""year"":"""&C106&""", ""couponrate"":"""&D106&""", ""benefittype"":"""&E106&""", ""benefitrate"":"""&F106&""", """&G$11&""":"""&G106&"""}" -> {"age":"1", "year":"13", "couponrate":"8", "benefittype":"A", "benefitrate":"800", "premiumrate":"1.01"} | J106: =IF(OR(I107="]", I106="[", I106="]"), "", ",") -> ,
... A171: ='EN60'!A$3 -> EN60 | B171: =B170 -> 1 | C171: =C170+1 -> 78 | D171: =IF(C171+B171=80,0,8) -> 8 | E171: A | F171: =IF(C171>7, 800, C171*100) -> 800 | G171: =G170 -> 1.01 | H171: ="INSERT INTO public.coupon ("&A$11&", "&B$11&", """&C$11&""", "&D$11&", "&E$11&", "&F$11&", "&G$11&") VALUES('"&A171&"', "&B171&", "&C171&", "&D171&", '"&E171&"',"&F171&", "&G171&");" -> INSERT INTO public.coupon (plancode, age, "year", couponrate, benefittype, benefitrate, premiumrate) VALUES('EN60', 1, 78, 8, 'A',800, 1.01); | I171: ="{""age"":"""&B171&""", ""year"":"""&C171&""", ""couponrate"":"""&D171&""", ""benefittype"":"""&E171&""", ""benefitrate"":"""&F171&""", """&G$11&""":"""&G171&"""}" -> {"age":"1", "year":"78", "couponrate":"8", "benefittype":"A", "benefitrate":"800", "premiumrate":"1.01"} | J171: =IF(OR(I172="]", I171="[", I171="]"), "", ",") -> ,
...

Sheet เงินคืน EN60(age 11-25)
A1: MatureTable | E1: 1.005 ครบสัญญา
A2: plancode | B2: maturerate | C2: premiumrate | E2: 1.005 มรณกรรม
A3: ='EN60'!A$3 -> EN60 | B3: ='EN60'!B$3 -> 808 | C3: ='EN60'!C$3 -> 1.01 | E3: ="INSERT INTO public.maturetable (plancode, maturerate, premiumrate) VALUES('"&A3&"', "&B3&", "&C3&");" -> INSERT INTO public.maturetable (plancode, maturerate, premiumrate) VALUES('EN60', 808, 1.01);
A5: coupontable | E5: ="INSERT INTO public.coupontable (id, returncash, ytable) VALUES('"&A7&"', "&B7&", '"&C7&"');" -> INSERT INTO public.coupontable (id, returncash, ytable) VALUES('EN60', 1, 'Y'); | I5: benefittype
A6: id | B6: returncash | C6: ytable | E6: returncash | F6: 0 | H6: ไม่มีเงินปันผล | I6: V = เอาเงินเวรคืนมาเป็นผลประโยชน์กรณีเสียชีวิต
A7: =A$3 -> EN60 | B7: ='EN60'!B$7 -> 1 | C7: ='EN60'!C$7 -> Y | F7: 1 | H7: มีเงินปันผล | I7: S = Max(เวรคืน, ผลประโยชน์กรณีเสียชีวิต)
E8: ytable | F8: N | H8: fix ปี ไม่ search ด้วยอายุ | I8: A = Max(เวรคืน, ผลประโยชน์กรณีเสียชีวิต, 1.005เท่าของเบี้ยที่จ่าย)
F9: Y | H9: ต้องส่งอายุไป search ด้วย | I9: อื่นๆ = แสดงผลประโยชน์กรณีเสียชีวิต
A10: coupon
A11: plancode | B11: age | C11: year | D11: couponrate | E11: benefittype | F11: benefitrate | G11: premiumrate | I11: ="[{""plancode"":"""&A12&""",""returncash"":"""&B$7&""",""ytable"":"""&C$7&""",""maturerate"":"""&B$3&""",""maturepmrate"":"""&C$3&""",""coupon"":[" -> [{"plancode":"EN60","returncash":"1","ytable":"Y","maturerate":"808","maturepmrate":"1.01","coupon":[
A12: ='EN60'!A$3 -> EN60 | B12: 11 | C12: 1 | D12: =IF(C12+B12=80,0,8) -> 8 | E12: A | F12: =IF(C12>7, 800, C12*100) -> 100 | G12: ='EN60'!C$3 -> 1.01 | H12: ="INSERT INTO public.coupon ("&A$11&", "&B$11&", """&C$11&""", "&D$11&", "&E$11&", "&F$11&", "&G$11&") VALUES('"&A12&"', "&B12&", "&C12&", "&D12&", '"&E12&"',"&F12&", "&G12&");" -> INSERT INTO public.coupon (plancode, age, "year", couponrate, benefittype, benefitrate, premiumrate) VALUES('EN60', 11, 1, 8, 'A',100, 1.01); | I12: ="{""age"":"""&B12&""", ""year"":"""&C12&""", ""couponrate"":"""&D12&""", ""benefittype"":"""&E12&""", ""benefitrate"":"""&F12&""", """&G$11&""":"""&G12&"""}" -> {"age":"11", "year":"1", "couponrate":"8", "benefittype":"A", "benefitrate":"100", "premiumrate":"1.01"} | J12: =IF(OR(I13="]", I12="[", I12="]"), "", ",") -> ,
A13: ='EN60'!A$3 -> EN60 | B13: =B12 -> 11 | C13: =C12+1 -> 2 | D13: =IF(C13+B13=80,0,8) -> 8 | E13: A | F13: =IF(C13>7, 800, C13*100) -> 200 | G13: =G12 -> 1.01 | H13: ="INSERT INTO public.coupon ("&A$11&", "&B$11&", """&C$11&""", "&D$11&", "&E$11&", "&F$11&", "&G$11&") VALUES('"&A13&"', "&B13&", "&C13&", "&D13&", '"&E13&"',"&F13&", "&G13&");" -> INSERT INTO public.coupon (plancode, age, "year", couponrate, benefittype, benefitrate, premiumrate) VALUES('EN60', 11, 2, 8, 'A',200, 1.01); | I13: ="{""age"":"""&B13&""", ""year"":"""&C13&""", ""couponrate"":"""&D13&""", ""benefittype"":"""&E13&""", ""benefitrate"":"""&F13&""", """&G$11&""":"""&G13&"""}" -> {"age":"11", "year":"2", "couponrate":"8", "benefittype":"A", "benefitrate":"200", "premiumrate":"1.01"} | J13: =IF(OR(I14="]", I13="[", I13="]"), "", ",") -> ,
A14: ='EN60'!A$3 -> EN60 | B14: =B13 -> 11 | C14: =C13+1 -> 3 | D14: =IF(C14+B14=80,0,8) -> 8 | E14: A | F14: =IF(C14>7, 800, C14*100) -> 300 | G14: =G13 -> 1.01 | H14: ="INSERT INTO public.coupon ("&A$11&", "&B$11&", """&C$11&""", "&D$11&", "&E$11&", "&F$11&", "&G$11&") VALUES('"&A14&"', "&B14&", "&C14&", "&D14&", '"&E14&"',"&F14&", "&G14&");" -> INSERT INTO public.coupon (plancode, age, "year", couponrate, benefittype, benefitrate, premiumrate) VALUES('EN60', 11, 3, 8, 'A',300, 1.01); | I14: ="{""age"":"""&B14&""", ""year"":"""&C14&""", ""couponrate"":"""&D14&""", ""benefittype"":"""&E14&""", ""benefitrate"":"""&F14&""", """&G$11&""":"""&G14&"""}" -> {"age":"11", "year":"3", "couponrate":"8", "benefittype":"A", "benefitrate":"300", "premiumrate":"1.01"} | J14: =IF(OR(I15="]", I14="[", I14="]"), "", ",") -> ,
A15: ='EN60'!A$3 -> EN60 | B15: =B14 -> 11 | C15: =C14+1 -> 4 | D15: =IF(C15+B15=80,0,8) -> 8 | E15: A | F15: =IF(C15>7, 800, C15*100) -> 400 | G15: =G14 -> 1.01 | H15: ="INSERT INTO public.coupon ("&A$11&", "&B$11&", """&C$11&""", "&D$11&", "&E$11&", "&F$11&", "&G$11&") VALUES('"&A15&"', "&B15&", "&C15&", "&D15&", '"&E15&"',"&F15&", "&G15&");" -> INSERT INTO public.coupon (plancode, age, "year", couponrate, benefittype, benefitrate, premiumrate) VALUES('EN60', 11, 4, 8, 'A',400, 1.01); | I15: ="{""age"":"""&B15&""", ""year"":"""&C15&""", ""couponrate"":"""&D15&""", ""benefittype"":"""&E15&""", ""benefitrate"":"""&F15&""", """&G$11&""":"""&G15&"""}" -> {"age":"11", "year":"4", "couponrate":"8", "benefittype":"A", "benefitrate":"400", "premiumrate":"1.01"} | J15: =IF(OR(I16="]", I15="[", I15="]"), "", ",") -> ,
A16: ='EN60'!A$3 -> EN60 | B16: =B15 -> 11 | C16: =C15+1 -> 5 | D16: =IF(C16+B16=80,0,8) -> 8 | E16: A | F16: =IF(C16>7, 800, C16*100) -> 500 | G16: =G15 -> 1.01 | H16: ="INSERT INTO public.coupon ("&A$11&", "&B$11&", """&C$11&""", "&D$11&", "&E$11&", "&F$11&", "&G$11&") VALUES('"&A16&"', "&B16&", "&C16&", "&D16&", '"&E16&"',"&F16&", "&G16&");" -> INSERT INTO public.coupon (plancode, age, "year", couponrate, benefittype, benefitrate, premiumrate) VALUES('EN60', 11, 5, 8, 'A',500, 1.01); | I16: ="{""age"":"""&B16&""", ""year"":"""&C16&""", ""couponrate"":"""&D16&""", ""benefittype"":"""&E16&""", ""benefitrate"":"""&F16&""", """&G$11&""":"""&G16&"""}" -> {"age":"11", "year":"5", "couponrate":"8", "benefittype":"A", "benefitrate":"500", "premiumrate":"1.01"} | J16: =IF(OR(I17="]", I16="[", I16="]"), "", ",") -> ,
A17: ='EN60'!A$3 -> EN60 | B17: =B16 -> 11 | C17: =C16+1 -> 6 | D17: =IF(C17+B17=80,0,8) -> 8 | E17: A | F17: =IF(C17>7, 800, C17*100) -> 600 | G17: =G16 -> 1.01 | H17: ="INSERT INTO public.coupon ("&A$11&", "&B$11&", """&C$11&""", "&D$11&", "&E$11&", "&F$11&", "&G$11&") VALUES('"&A17&"', "&B17&", "&C17&", "&D17&", '"&E17&"',"&F17&", "&G17&");" -> INSERT INTO public.coupon (plancode, age, "year", couponrate, benefittype, benefitrate, premiumrate) VALUES('EN60', 11, 6, 8, 'A',600, 1.01); | I17: ="{""age"":"""&B17&""", ""year"":"""&C17&""", ""couponrate"":"""&D17&""", ""benefittype"":"""&E17&""", ""benefitrate"":"""&F17&""", """&G$11&""":"""&G17&"""}" -> {"age":"11", "year":"6", "couponrate":"8", "benefittype":"A", "benefitrate":"600", "premiumrate":"1.01"} | J17: =IF(OR(I18="]", I17="[", I17="]"), "", ",") -> ,
A18: ='EN60'!A$3 -> EN60 | B18: =B17 -> 11 | C18: =C17+1 -> 7 | D18: =IF(C18+B18=80,0,8) -> 8 | E18: A | F18: =IF(C18>7, 800, C18*100) -> 700 | G18: =G17 -> 1.01 | H18: ="INSERT INTO public.coupon ("&A$11&", "&B$11&", """&C$11&""", "&D$11&", "&E$11&", "&F$11&", "&G$11&") VALUES('"&A18&"', "&B18&", "&C18&", "&D18&", '"&E18&"',"&F18&", "&G18&");" -> INSERT INTO public.coupon (plancode, age, "year", couponrate, benefittype, benefitrate, premiumrate) VALUES('EN60', 11, 7, 8, 'A',700, 1.01); | I18: ="{""age"":"""&B18&""", ""year"":"""&C18&""", ""couponrate"":"""&D18&""", ""benefittype"":"""&E18&""", ""benefitrate"":"""&F18&""", """&G$11&""":"""&G18&"""}" -> {"age":"11", "year":"7", "couponrate":"8", "benefittype":"A", "benefitrate":"700", "premiumrate":"1.01"} | J18: =IF(OR(I19="]", I18="[", I18="]"), "", ",") -> ,
A19: ='EN60'!A$3 -> EN60 | B19: =B18 -> 11 | C19: =C18+1 -> 8 | D19: =IF(C19+B19=80,0,8) -> 8 | E19: A | F19: =IF(C19>7, 800, C19*100) -> 800 | G19: =G18 -> 1.01 | H19: ="INSERT INTO public.coupon ("&A$11&", "&B$11&", """&C$11&""", "&D$11&", "&E$11&", "&F$11&", "&G$11&") VALUES('"&A19&"', "&B19&", "&C19&", "&D19&", '"&E19&"',"&F19&", "&G19&");" -> INSERT INTO public.coupon (plancode, age, "year", couponrate, benefittype, benefitrate, premiumrate) VALUES('EN60', 11, 8, 8, 'A',800, 1.01); | I19: ="{""age"":"""&B19&""", ""year"":"""&C19&""", ""couponrate"":"""&D19&""", ""benefittype"":"""&E19&""", ""benefitrate"":"""&F19&""", """&G$11&""":"""&G19&"""}" -> {"age":"11", "year":"8", "couponrate":"8", "benefittype":"A", "benefitrate":"800", "premiumrate":"1.01"} | J19: =IF(OR(I20="]", I19="[", I19="]"), "", ",") -> ,
A20: ='EN60'!A$3 -> EN60 | B20: =B19 -> 11 | C20: =C19+1 -> 9 | D20: =IF(C20+B20=80,0,8) -> 8 | E20: A | F20: =IF(C20>7, 800, C20*100) -> 800 | G20: =G19 -> 1.01 | H20: ="INSERT INTO public.coupon ("&A$11&", "&B$11&", """&C$11&""", "&D$11&", "&E$11&", "&F$11&", "&G$11&") VALUES('"&A20&"', "&B20&", "&C20&", "&D20&", '"&E20&"',"&F20&", "&G20&");" -> INSERT INTO public.coupon (plancode, age, "year", couponrate, benefittype, benefitrate, premiumrate) VALUES('EN60', 11, 9, 8, 'A',800, 1.01); | I20: ="{""age"":"""&B20&""", ""year"":"""&C20&""", ""couponrate"":"""&D20&""", ""benefittype"":"""&E20&""", ""benefitrate"":"""&F20&""", """&G$11&""":"""&G20&"""}" -> {"age":"11", "year":"9", "couponrate":"8", "benefittype":"A", "benefitrate":"800", "premiumrate":"1.01"} | J20: =IF(OR(I21="]", I20="[", I20="]"), "", ",") -> ,
A21: ='EN60'!A$3 -> EN60 | B21: =B20 -> 11 | C21: =C20+1 -> 10 | D21: =IF(C21+B21=80,0,8) -> 8 | E21: A | F21: =IF(C21>7, 800, C21*100) -> 800 | G21: =G20 -> 1.01 | H21: ="INSERT INTO public.coupon ("&A$11&", "&B$11&", """&C$11&""", "&D$11&", "&E$11&", "&F$11&", "&G$11&") VALUES('"&A21&"', "&B21&", "&C21&", "&D21&", '"&E21&"',"&F21&", "&G21&");" -> INSERT INTO public.coupon (plancode, age, "year", couponrate, benefittype, benefitrate, premiumrate) VALUES('EN60', 11, 10, 8, 'A',800, 1.01); | I21: ="{""age"":"""&B21&""", ""year"":"""&C21&""", ""couponrate"":"""&D21&""", ""benefittype"":"""&E21&""", ""benefitrate"":"""&F21&""", """&G$11&""":"""&G21&"""}" -> {"age":"11", "year":"10", "couponrate":"8", "benefittype":"A", "benefitrate":"800", "premiumrate":"1.01"} | J21: =IF(OR(I22="]", I21="[", I21="]"), "", ",") -> ,
A22: ='EN60'!A$3 -> EN60 | B22: =B21 -> 11 | C22: =C21+1 -> 11 | D22: =IF(C22+B22=80,0,8) -> 8 | E22: A | F22: =IF(C22>7, 800, C22*100) -> 800 | G22: =G21 -> 1.01 | H22: ="INSERT INTO public.coupon ("&A$11&", "&B$11&", """&C$11&""", "&D$11&", "&E$11&", "&F$11&", "&G$11&") VALUES('"&A22&"', "&B22&", "&C22&", "&D22&", '"&E22&"',"&F22&", "&G22&");" -> INSERT INTO public.coupon (plancode, age, "year", couponrate, benefittype, benefitrate, premiumrate) VALUES('EN60', 11, 11, 8, 'A',800, 1.01); | I22: ="{""age"":"""&B22&""", ""year"":"""&C22&""", ""couponrate"":"""&D22&""", ""benefittype"":"""&E22&""", ""benefitrate"":"""&F22&""", """&G$11&""":"""&G22&"""}" -> {"age":"11", "year":"11", "couponrate":"8", "benefittype":"A", "benefitrate":"800", "premiumrate":"1.01"} | J22: =IF(OR(I23="]", I22="[", I22="]"), "", ",") -> ,
A23: ='EN60'!A$3 -> EN60 | B23: =B22 -> 11 | C23: =C22+1 -> 12 | D23: =IF(C23+B23=80,0,8) -> 8 | E23: A | F23: =IF(C23>7, 800, C23*100) -> 800 | G23: =G22 -> 1.01 | H23: ="INSERT INTO public.coupon ("&A$11&", "&B$11&", """&C$11&""", "&D$11&", "&E$11&", "&F$11&", "&G$11&") VALUES('"&A23&"', "&B23&", "&C23&", "&D23&", '"&E23&"',"&F23&", "&G23&");" -> INSERT INTO public.coupon (plancode, age, "year", couponrate, benefittype, benefitrate, premiumrate) VALUES('EN60', 11, 12, 8, 'A',800, 1.01); | I23: ="{""age"":"""&B23&""", ""year"":"""&C23&""", ""couponrate"":"""&D23&""", ""benefittype"":"""&E23&""", ""benefitrate"":"""&F23&""", """&G$11&""":"""&G23&"""}" -> {"age":"11", "year":"12", "couponrate":"8", "benefittype":"A", "benefitrate":"800", "premiumrate":"1.01"} | J23: =IF(OR(I24="]", I23="[", I23="]"), "", ",") -> ,
A24: ='EN60'!A$3 -> EN60 | B24: =B23 -> 11 | C24: =C23+1 -> 13 | D24: =IF(C24+B24=80,0,8) -> 8 | E24: A | F24: =IF(C24>7, 800, C24*100) -> 800 | G24: =G23 -> 1.01 | H24: ="INSERT INTO public.coupon ("&A$11&", "&B$11&", """&C$11&""", "&D$11&", "&E$11&", "&F$11&", "&G$11&") VALUES('"&A24&"', "&B24&", "&C24&", "&D24&", '"&E24&"',"&F24&", "&G24&");" -> INSERT INTO public.coupon (plancode, age, "year", couponrate, benefittype, benefitrate, premiumrate) VALUES('EN60', 11, 13, 8, 'A',800, 1.01); | I24: ="{""age"":"""&B24&""", ""year"":"""&C24&""", ""couponrate"":"""&D24&""", ""benefittype"":"""&E24&""", ""benefitrate"":"""&F24&""", """&G$11&""":"""&G24&"""}" -> {"age":"11", "year":"13", "couponrate":"8", "benefittype":"A", "benefitrate":"800", "premiumrate":"1.01"} | J24: =IF(OR(I25="]", I24="[", I24="]"), "", ",") -> ,
... A79: ='EN60'!A$3 -> EN60 | B79: =B78 -> 11 | C79: =C78+1 -> 68 | D79: =IF(C79+B79=80,0,8) -> 8 | E79: A | F79: =IF(C79>7, 800, C79*100) -> 800 | G79: =G78 -> 1.01 | H79: ="INSERT INTO public.coupon ("&A$11&", "&B$11&", """&C$11&""", "&D$11&", "&E$11&", "&F$11&", "&G$11&") VALUES('"&A79&"', "&B79&", "&C79&", "&D79&", '"&E79&"',"&F79&", "&G79&");" -> INSERT INTO public.coupon (plancode, age, "year", couponrate, benefittype, benefitrate, premiumrate) VALUES('EN60', 11, 68, 8, 'A',800, 1.01); | I79: ="{""age"":"""&B79&""", ""year"":"""&C79&""", ""couponrate"":"""&D79&""", ""benefittype"":"""&E79&""", ""benefitrate"":"""&F79&""", """&G$11&""":"""&G79&"""}" -> {"age":"11", "year":"68", "couponrate":"8", "benefittype":"A", "benefitrate":"800", "premiumrate":"1.01"} | J79: =IF(OR(I80="]", I79="[", I79="]"), "", ",") -> ,
A80: ='EN60'!A$3 -> EN60 | B80: =B79 -> 11 | C80: =C79+1 -> 69 | D80: =IF(C80+B80=80,0,8) -> 0 | E80: A | F80: =IF(C80>7, 800, C80*100) -> 800 | G80: =G79 -> 1.01 | H80: ="INSERT INTO public.coupon ("&A$11&", "&B$11&", """&C$11&""", "&D$11&", "&E$11&", "&F$11&", "&G$11&") VALUES('"&A80&"', "&B80&", "&C80&", "&D80&", '"&E80&"',"&F80&", "&G80&");" -> INSERT INTO public.coupon (plancode, age, "year", couponrate, benefittype, benefitrate, premiumrate) VALUES('EN60', 11, 69, 0, 'A',800, 1.01); | I80: ="{""age"":"""&B80&""", ""year"":"""&C80&""", ""couponrate"":"""&D80&""", ""benefittype"":"""&E80&""", ""benefitrate"":"""&F80&""", """&G$11&""":"""&G80&"""}" -> {"age":"11", "year":"69", "couponrate":"0", "benefittype":"A", "benefitrate":"800", "premiumrate":"1.01"}
I81: ]}]
A82: plancode | B82: age | C82: year | D82: couponrate | E82: benefittype | F82: benefitrate | G82: premiumrate | I82: ="[{""plancode"":"""&A83&""",""returncash"":"""&B$7&""",""ytable"":"""&C$7&""",""maturerate"":"""&B$3&""",""maturepmrate"":"""&C$3&""",""coupon"":[" -> [{"plancode":"EN60","returncash":"1","ytable":"Y","maturerate":"808","maturepmrate":"1.01","coupon":[
A83: ='EN60'!A$3 -> EN60 | B83: 12 | C83: 1 | D83: =IF(C83+B83=80,0,8) -> 8 | E83: A | F83: =IF(C83>7, 800, C83*100) -> 100 | G83: ='EN60'!C$3 -> 1.01 | H83: ="INSERT INTO public.coupon ("&A$11&", "&B$11&", """&C$11&""", "&D$11&", "&E$11&", "&F$11&", "&G$11&") VALUES('"&A83&"', "&B83&", "&C83&", "&D83&", '"&E83&"',"&F83&", "&G83&");" -> INSERT INTO public.coupon (plancode, age, "year", couponrate, benefittype, benefitrate, premiumrate) VALUES('EN60', 12, 1, 8, 'A',100, 1.01); | I83: ="{""age"":"""&B83&""", ""year"":"""&C83&""", ""couponrate"":"""&D83&""", ""benefittype"":"""&E83&""", ""benefitrate"":"""&F83&""", """&G$11&""":"""&G83&"""}" -> {"age":"12", "year":"1", "couponrate":"8", "benefittype":"A", "benefitrate":"100", "premiumrate":"1.01"} | J83: =IF(OR(I84="]", I83="[", I83="]"), "", ",") -> ,
A84: ='EN60'!A$3 -> EN60 | B84: =B83 -> 12 | C84: =C83+1 -> 2 | D84: =IF(C84+B84=80,0,8) -> 8 | E84: A | F84: =IF(C84>7, 800, C84*100) -> 200 | G84: =G83 -> 1.01 | H84: ="INSERT INTO public.coupon ("&A$11&", "&B$11&", """&C$11&""", "&D$11&", "&E$11&", "&F$11&", "&G$11&") VALUES('"&A84&"', "&B84&", "&C84&", "&D84&", '"&E84&"',"&F84&", "&G84&");" -> INSERT INTO public.coupon (plancode, age, "year", couponrate, benefittype, benefitrate, premiumrate) VALUES('EN60', 12, 2, 8, 'A',200, 1.01); | I84: ="{""age"":"""&B84&""", ""year"":"""&C84&""", ""couponrate"":"""&D84&""", ""benefittype"":"""&E84&""", ""benefitrate"":"""&F84&""", """&G$11&""":"""&G84&"""}" -> {"age":"12", "year":"2", "couponrate":"8", "benefittype":"A", "benefitrate":"200", "premiumrate":"1.01"} | J84: =IF(OR(I85="]", I84="[", I84="]"), "", ",") -> ,
A85: ='EN60'!A$3 -> EN60 | B85: =B84 -> 12 | C85: =C84+1 -> 3 | D85: =IF(C85+B85=80,0,8) -> 8 | E85: A | F85: =IF(C85>7, 800, C85*100) -> 300 | G85: =G84 -> 1.01 | H85: ="INSERT INTO public.coupon ("&A$11&", "&B$11&", """&C$11&""", "&D$11&", "&E$11&", "&F$11&", "&G$11&") VALUES('"&A85&"', "&B85&", "&C85&", "&D85&", '"&E85&"',"&F85&", "&G85&");" -> INSERT INTO public.coupon (plancode, age, "year", couponrate, benefittype, benefitrate, premiumrate) VALUES('EN60', 12, 3, 8, 'A',300, 1.01); | I85: ="{""age"":"""&B85&""", ""year"":"""&C85&""", ""couponrate"":"""&D85&""", ""benefittype"":"""&E85&""", ""benefitrate"":"""&F85&""", """&G$11&""":"""&G85&"""}" -> {"age":"12", "year":"3", "couponrate":"8", "benefittype":"A", "benefitrate":"300", "premiumrate":"1.01"} | J85: =IF(OR(I86="]", I85="[", I85="]"), "", ",") -> ,
A86: ='EN60'!A$3 -> EN60 | B86: =B85 -> 12 | C86: =C85+1 -> 4 | D86: =IF(C86+B86=80,0,8) -> 8 | E86: A | F86: =IF(C86>7, 800, C86*100) -> 400 | G86: =G85 -> 1.01 | H86: ="INSERT INTO public.coupon ("&A$11&", "&B$11&", """&C$11&""", "&D$11&", "&E$11&", "&F$11&", "&G$11&") VALUES('"&A86&"', "&B86&", "&C86&", "&D86&", '"&E86&"',"&F86&", "&G86&");" -> INSERT INTO public.coupon (plancode, age, "year", couponrate, benefittype, benefitrate, premiumrate) VALUES('EN60', 12, 4, 8, 'A',400, 1.01); | I86: ="{""age"":"""&B86&""", ""year"":"""&C86&""", ""couponrate"":"""&D86&""", ""benefittype"":"""&E86&""", ""benefitrate"":"""&F86&""", """&G$11&""":"""&G86&"""}" -> {"age":"12", "year":"4", "couponrate":"8", "benefittype":"A", "benefitrate":"400", "premiumrate":"1.01"} | J86: =IF(OR(I87="]", I86="[", I86="]"), "", ",") -> ,
A87: ='EN60'!A$3 -> EN60 | B87: =B86 -> 12 | C87: =C86+1 -> 5 | D87: =IF(C87+B87=80,0,8) -> 8 | E87: A | F87: =IF(C87>7, 800, C87*100) -> 500 | G87: =G86 -> 1.01 | H87: ="INSERT INTO public.coupon ("&A$11&", "&B$11&", """&C$11&""", "&D$11&", "&E$11&", "&F$11&", "&G$11&") VALUES('"&A87&"', "&B87&", "&C87&", "&D87&", '"&E87&"',"&F87&", "&G87&");" -> INSERT INTO public.coupon (plancode, age, "year", couponrate, benefittype, benefitrate, premiumrate) VALUES('EN60', 12, 5, 8, 'A',500, 1.01); | I87: ="{""age"":"""&B87&""", ""year"":"""&C87&""", ""couponrate"":"""&D87&""", ""benefittype"":"""&E87&""", ""benefitrate"":"""&F87&""", """&G$11&""":"""&G87&"""}" -> {"age":"12", "year":"5", "couponrate":"8", "benefittype":"A", "benefitrate":"500", "premiumrate":"1.01"} | J87: =IF(OR(I88="]", I87="[", I87="]"), "", ",") -> ,
A88: ='EN60'!A$3 -> EN60 | B88: =B87 -> 12 | C88: =C87+1 -> 6 | D88: =IF(C88+B88=80,0,8) -> 8 | E88: A | F88: =IF(C88>7, 800, C88*100) -> 600 | G88: =G87 -> 1.01 | H88: ="INSERT INTO public.coupon ("&A$11&", "&B$11&", """&C$11&""", "&D$11&", "&E$11&", "&F$11&", "&G$11&") VALUES('"&A88&"', "&B88&", "&C88&", "&D88&", '"&E88&"',"&F88&", "&G88&");" -> INSERT INTO public.coupon (plancode, age, "year", couponrate, benefittype, benefitrate, premiumrate) VALUES('EN60', 12, 6, 8, 'A',600, 1.01); | I88: ="{""age"":"""&B88&""", ""year"":"""&C88&""", ""couponrate"":"""&D88&""", ""benefittype"":"""&E88&""", ""benefitrate"":"""&F88&""", """&G$11&""":"""&G88&"""}" -> {"age":"12", "year":"6", "couponrate":"8", "benefittype":"A", "benefitrate":"600", "premiumrate":"1.01"} | J88: =IF(OR(I89="]", I88="[", I88="]"), "", ",") -> ,
A89: ='EN60'!A$3 -> EN60 | B89: =B88 -> 12 | C89: =C88+1 -> 7 | D89: =IF(C89+B89=80,0,8) -> 8 | E89: A | F89: =IF(C89>7, 800, C89*100) -> 700 | G89: =G88 -> 1.01 | H89: ="INSERT INTO public.coupon ("&A$11&", "&B$11&", """&C$11&""", "&D$11&", "&E$11&", "&F$11&", "&G$11&") VALUES('"&A89&"', "&B89&", "&C89&", "&D89&", '"&E89&"',"&F89&", "&G89&");" -> INSERT INTO public.coupon (plancode, age, "year", couponrate, benefittype, benefitrate, premiumrate) VALUES('EN60', 12, 7, 8, 'A',700, 1.01); | I89: ="{""age"":"""&B89&""", ""year"":"""&C89&""", ""couponrate"":"""&D89&""", ""benefittype"":"""&E89&""", ""benefitrate"":"""&F89&""", """&G$11&""":"""&G89&"""}" -> {"age":"12", "year":"7", "couponrate":"8", "benefittype":"A", "benefitrate":"700", "premiumrate":"1.01"} | J89: =IF(OR(I90="]", I89="[", I89="]"), "", ",") -> ,
A90: ='EN60'!A$3 -> EN60 | B90: =B89 -> 12 | C90: =C89+1 -> 8 | D90: =IF(C90+B90=80,0,8) -> 8 | E90: A | F90: =IF(C90>7, 800, C90*100) -> 800 | G90: =G89 -> 1.01 | H90: ="INSERT INTO public.coupon ("&A$11&", "&B$11&", """&C$11&""", "&D$11&", "&E$11&", "&F$11&", "&G$11&") VALUES('"&A90&"', "&B90&", "&C90&", "&D90&", '"&E90&"',"&F90&", "&G90&");" -> INSERT INTO public.coupon (plancode, age, "year", couponrate, benefittype, benefitrate, premiumrate) VALUES('EN60', 12, 8, 8, 'A',800, 1.01); | I90: ="{""age"":"""&B90&""", ""year"":"""&C90&""", ""couponrate"":"""&D90&""", ""benefittype"":"""&E90&""", ""benefitrate"":"""&F90&""", """&G$11&""":"""&G90&"""}" -> {"age":"12", "year":"8", "couponrate":"8", "benefittype":"A", "benefitrate":"800", "premiumrate":"1.01"} | J90: =IF(OR(I91="]", I90="[", I90="]"), "", ",") -> ,
A91: ='EN60'!A$3 -> EN60 | B91: =B90 -> 12 | C91: =C90+1 -> 9 | D91: =IF(C91+B91=80,0,8) -> 8 | E91: A | F91: =IF(C91>7, 800, C91*100) -> 800 | G91: =G90 -> 1.01 | H91: ="INSERT INTO public.coupon ("&A$11&", "&B$11&", """&C$11&""", "&D$11&", "&E$11&", "&F$11&", "&G$11&") VALUES('"&A91&"', "&B91&", "&C91&", "&D91&", '"&E91&"',"&F91&", "&G91&");" -> INSERT INTO public.coupon (plancode, age, "year", couponrate, benefittype, benefitrate, premiumrate) VALUES('EN60', 12, 9, 8, 'A',800, 1.01); | I91: ="{""age"":"""&B91&""", ""year"":"""&C91&""", ""couponrate"":"""&D91&""", ""benefittype"":"""&E91&""", ""benefitrate"":"""&F91&""", """&G$11&""":"""&G91&"""}" -> {"age":"12", "year":"9", "couponrate":"8", "benefittype":"A", "benefitrate":"800", "premiumrate":"1.01"} | J91: =IF(OR(I92="]", I91="[", I91="]"), "", ",") -> ,
A92: ='EN60'!A$3 -> EN60 | B92: =B91 -> 12 | C92: =C91+1 -> 10 | D92: =IF(C92+B92=80,0,8) -> 8 | E92: A | F92: =IF(C92>7, 800, C92*100) -> 800 | G92: =G91 -> 1.01 | H92: ="INSERT INTO public.coupon ("&A$11&", "&B$11&", """&C$11&""", "&D$11&", "&E$11&", "&F$11&", "&G$11&") VALUES('"&A92&"', "&B92&", "&C92&", "&D92&", '"&E92&"',"&F92&", "&G92&");" -> INSERT INTO public.coupon (plancode, age, "year", couponrate, benefittype, benefitrate, premiumrate) VALUES('EN60', 12, 10, 8, 'A',800, 1.01); | I92: ="{""age"":"""&B92&""", ""year"":"""&C92&""", ""couponrate"":"""&D92&""", ""benefittype"":"""&E92&""", ""benefitrate"":"""&F92&""", """&G$11&""":"""&G92&"""}" -> {"age":"12", "year":"10", "couponrate":"8", "benefittype":"A", "benefitrate":"800", "premiumrate":"1.01"} | J92: =IF(OR(I93="]", I92="[", I92="]"), "", ",") -> ,
A93: ='EN60'!A$3 -> EN60 | B93: =B92 -> 12 | C93: =C92+1 -> 11 | D93: =IF(C93+B93=80,0,8) -> 8 | E93: A | F93: =IF(C93>7, 800, C93*100) -> 800 | G93: =G92 -> 1.01 | H93: ="INSERT INTO public.coupon ("&A$11&", "&B$11&", """&C$11&""", "&D$11&", "&E$11&", "&F$11&", "&G$11&") VALUES('"&A93&"', "&B93&", "&C93&", "&D93&", '"&E93&"',"&F93&", "&G93&");" -> INSERT INTO public.coupon (plancode, age, "year", couponrate, benefittype, benefitrate, premiumrate) VALUES('EN60', 12, 11, 8, 'A',800, 1.01); | I93: ="{""age"":"""&B93&""", ""year"":"""&C93&""", ""couponrate"":"""&D93&""", ""benefittype"":"""&E93&""", ""benefitrate"":"""&F93&""", """&G$11&""":"""&G93&"""}" -> {"age":"12", "year":"11", "couponrate":"8", "benefittype":"A", "benefitrate":"800", "premiumrate":"1.01"} | J93: =IF(OR(I94="]", I93="[", I93="]"), "", ",") -> ,
A94: ='EN60'!A$3 -> EN60 | B94: =B93 -> 12 | C94: =C93+1 -> 12 | D94: =IF(C94+B94=80,0,8) -> 8 | E94: A | F94: =IF(C94>7, 800, C94*100) -> 800 | G94: =G93 -> 1.01 | H94: ="INSERT INTO public.coupon ("&A$11&", "&B$11&", """&C$11&""", "&D$11&", "&E$11&", "&F$11&", "&G$11&") VALUES('"&A94&"', "&B94&", "&C94&", "&D94&", '"&E94&"',"&F94&", "&G94&");" -> INSERT INTO public.coupon (plancode, age, "year", couponrate, benefittype, benefitrate, premiumrate) VALUES('EN60', 12, 12, 8, 'A',800, 1.01); | I94: ="{""age"":"""&B94&""", ""year"":"""&C94&""", ""couponrate"":"""&D94&""", ""benefittype"":"""&E94&""", ""benefitrate"":"""&F94&""", """&G$11&""":"""&G94&"""}" -> {"age":"12", "year":"12", "couponrate":"8", "benefittype":"A", "benefitrate":"800", "premiumrate":"1.01"} | J94: =IF(OR(I95="]", I94="[", I94="]"), "", ",") -> ,
A95: ='EN60'!A$3 -> EN60 | B95: =B94 -> 12 | C95: =C94+1 -> 13 | D95: =IF(C95+B95=80,0,8) -> 8 | E95: A | F95: =IF(C95>7, 800, C95*100) -> 800 | G95: =G94 -> 1.01 | H95: ="INSERT INTO public.coupon ("&A$11&", "&B$11&", """&C$11&""", "&D$11&", "&E$11&", "&F$11&", "&G$11&") VALUES('"&A95&"', "&B95&", "&C95&", "&D95&", '"&E95&"',"&F95&", "&G95&");" -> INSERT INTO public.coupon (plancode, age, "year", couponrate, benefittype, benefitrate, premiumrate) VALUES('EN60', 12, 13, 8, 'A',800, 1.01); | I95: ="{""age"":"""&B95&""", ""year"":"""&C95&""", ""couponrate"":"""&D95&""", ""benefittype"":"""&E95&""", ""benefitrate"":"""&F95&""", """&G$11&""":"""&G95&"""}" -> {"age":"12", "year":"13", "couponrate":"8", "benefittype":"A", "benefitrate":"800", "premiumrate":"1.01"} | J95: =IF(OR(I96="]", I95="[", I95="]"), "", ",") -> ,
...

Sheet เงินคืน EN60(age 16-45)
A1: MatureTable | E1: 1.005 ครบสัญญา
A2: plancode | B2: maturerate | C2: premiumrate | E2: 1.005 มรณกรรม
A3: ='EN60'!A$3 -> EN60 | B3: ='EN60'!B$3 -> 808 | C3: ='EN60'!C$3 -> 1.01 | E3: ="INSERT INTO public.maturetable (plancode, maturerate, premiumrate) VALUES('"&A3&"', "&B3&", "&C3&");" -> INSERT INTO public.maturetable (plancode, maturerate, premiumrate) VALUES('EN60', 808, 1.01);
A5: coupontable | E5: ="INSERT INTO public.coupontable (id, returncash, ytable) VALUES('"&A7&"', "&B7&", '"&C7&"');" -> INSERT INTO public.coupontable (id, returncash, ytable) VALUES('EN60', 1, 'Y'); | I5: benefittype
A6: id | B6: returncash | C6: ytable | E6: returncash | F6: 0 | H6: ไม่มีเงินปันผล | I6: V = เอาเงินเวรคืนมาเป็นผลประโยชน์กรณีเสียชีวิต
A7: =A$3 -> EN60 | B7: ='EN60'!B$7 -> 1 | C7: ='EN60'!C$7 -> Y | F7: 1 | H7: มีเงินปันผล | I7: S = Max(เวรคืน, ผลประโยชน์กรณีเสียชีวิต)
E8: ytable | F8: N | H8: fix ปี ไม่ search ด้วยอายุ | I8: A = Max(เวรคืน, ผลประโยชน์กรณีเสียชีวิต, 1.005เท่าของเบี้ยที่จ่าย)
F9: Y | H9: ต้องส่งอายุไป search ด้วย | I9: อื่นๆ = แสดงผลประโยชน์กรณีเสียชีวิต
A10: coupon
A11: plancode | B11: age | C11: year | D11: couponrate | E11: benefittype | F11: benefitrate | G11: premiumrate | I11: ="[{""plancode"":"""&A12&""",""returncash"":"""&B$7&""",""ytable"":"""&C$7&""",""maturerate"":"""&B$3&""",""maturepmrate"":"""&C$3&""",""coupon"":[" -> [{"plancode":"EN60","returncash":"1","ytable":"Y","maturerate":"808","maturepmrate":"1.01","coupon":[
A12: ='EN60'!A$3 -> EN60 | B12: 26 | C12: 1 | D12: =IF(C12+B12=80,0,8) -> 8 | E12: A | F12: =IF(C12>7, 800, C12*100) -> 100 | G12: ='EN60'!C$3 -> 1.01 | H12: ="INSERT INTO public.coupon ("&A$11&", "&B$11&", """&C$11&""", "&D$11&", "&E$11&", "&F$11&", "&G$11&") VALUES('"&A12&"', "&B12&", "&C12&", "&D12&", '"&E12&"',"&F12&", "&G12&");" -> INSERT INTO public.coupon (plancode, age, "year", couponrate, benefittype, benefitrate, premiumrate) VALUES('EN60', 26, 1, 8, 'A',100, 1.01); | I12: ="{""age"":"""&B12&""", ""year"":"""&C12&""", ""couponrate"":"""&D12&""", ""benefittype"":"""&E12&""", ""benefitrate"":"""&F12&""", """&G$11&""":"""&G12&"""}" -> {"age":"26", "year":"1", "couponrate":"8", "benefittype":"A", "benefitrate":"100", "premiumrate":"1.01"} | J12: =IF(OR(I13="]", I12="[", I12="]"), "", ",") -> ,
A13: ='EN60'!A$3 -> EN60 | B13: =B12 -> 26 | C13: =C12+1 -> 2 | D13: =IF(C13+B13=80,0,8) -> 8 | E13: A | F13: =IF(C13>7, 800, C13*100) -> 200 | G13: =G12 -> 1.01 | H13: ="INSERT INTO public.coupon ("&A$11&", "&B$11&", """&C$11&""", "&D$11&", "&E$11&", "&F$11&", "&G$11&") VALUES('"&A13&"', "&B13&", "&C13&", "&D13&", '"&E13&"',"&F13&", "&G13&");" -> INSERT INTO public.coupon (plancode, age, "year", couponrate, benefittype, benefitrate, premiumrate) VALUES('EN60', 26, 2, 8, 'A',200, 1.01); | I13: ="{""age"":"""&B13&""", ""year"":"""&C13&""", ""couponrate"":"""&D13&""", ""benefittype"":"""&E13&""", ""benefitrate"":"""&F13&""", """&G$11&""":"""&G13&"""}" -> {"age":"26", "year":"2", "couponrate":"8", "benefittype":"A", "benefitrate":"200", "premiumrate":"1.01"} | J13: =IF(OR(I14="]", I13="[", I13="]"), "", ",") -> ,
A14: ='EN60'!A$3 -> EN60 | B14: =B13 -> 26 | C14: =C13+1 -> 3 | D14: =IF(C14+B14=80,0,8) -> 8 | E14: A | F14: =IF(C14>7, 800, C14*100) -> 300 | G14: =G13 -> 1.01 | H14: ="INSERT INTO public.coupon ("&A$11&", "&B$11&", """&C$11&""", "&D$11&", "&E$11&", "&F$11&", "&G$11&") VALUES('"&A14&"', "&B14&", "&C14&", "&D14&", '"&E14&"',"&F14&", "&G14&");" -> INSERT INTO public.coupon (plancode, age, "year", couponrate, benefittype, benefitrate, premiumrate) VALUES('EN60', 26, 3, 8, 'A',300, 1.01); | I14: ="{""age"":"""&B14&""", ""year"":"""&C14&""", ""couponrate"":"""&D14&""", ""benefittype"":"""&E14&""", ""benefitrate"":"""&F14&""", """&G$11&""":"""&G14&"""}" -> {"age":"26", "year":"3", "couponrate":"8", "benefittype":"A", "benefitrate":"300", "premiumrate":"1.01"} | J14: =IF(OR(I15="]", I14="[", I14="]"), "", ",") -> ,
A15: ='EN60'!A$3 -> EN60 | B15: =B14 -> 26 | C15: =C14+1 -> 4 | D15: =IF(C15+B15=80,0,8) -> 8 | E15: A | F15: =IF(C15>7, 800, C15*100) -> 400 | G15: =G14 -> 1.01 | H15: ="INSERT INTO public.coupon ("&A$11&", "&B$11&", """&C$11&""", "&D$11&", "&E$11&", "&F$11&", "&G$11&") VALUES('"&A15&"', "&B15&", "&C15&", "&D15&", '"&E15&"',"&F15&", "&G15&");" -> INSERT INTO public.coupon (plancode, age, "year", couponrate, benefittype, benefitrate, premiumrate) VALUES('EN60', 26, 4, 8, 'A',400, 1.01); | I15: ="{""age"":"""&B15&""", ""year"":"""&C15&""", ""couponrate"":"""&D15&""", ""benefittype"":"""&E15&""", ""benefitrate"":"""&F15&""", """&G$11&""":"""&G15&"""}" -> {"age":"26", "year":"4", "couponrate":"8", "benefittype":"A", "benefitrate":"400", "premiumrate":"1.01"} | J15: =IF(OR(I16="]", I15="[", I15="]"), "", ",") -> ,
A16: ='EN60'!A$3 -> EN60 | B16: =B15 -> 26 | C16: =C15+1 -> 5 | D16: =IF(C16+B16=80,0,8) -> 8 | E16: A | F16: =IF(C16>7, 800, C16*100) -> 500 | G16: =G15 -> 1.01 | H16: ="INSERT INTO public.coupon ("&A$11&", "&B$11&", """&C$11&""", "&D$11&", "&E$11&", "&F$11&", "&G$11&") VALUES('"&A16&"', "&B16&", "&C16&", "&D16&", '"&E16&"',"&F16&", "&G16&");" -> INSERT INTO public.coupon (plancode, age, "year", couponrate, benefittype, benefitrate, premiumrate) VALUES('EN60', 26, 5, 8, 'A',500, 1.01); | I16: ="{""age"":"""&B16&""", ""year"":"""&C16&""", ""couponrate"":"""&D16&""", ""benefittype"":"""&E16&""", ""benefitrate"":"""&F16&""", """&G$11&""":"""&G16&"""}" -> {"age":"26", "year":"5", "couponrate":"8", "benefittype":"A", "benefitrate":"500", "premiumrate":"1.01"} | J16: =IF(OR(I17="]", I16="[", I16="]"), "", ",") -> ,
A17: ='EN60'!A$3 -> EN60 | B17: =B16 -> 26 | C17: =C16+1 -> 6 | D17: =IF(C17+B17=80,0,8) -> 8 | E17: A | F17: =IF(C17>7, 800, C17*100) -> 600 | G17: =G16 -> 1.01 | H17: ="INSERT INTO public.coupon ("&A$11&", "&B$11&", """&C$11&""", "&D$11&", "&E$11&", "&F$11&", "&G$11&") VALUES('"&A17&"', "&B17&", "&C17&", "&D17&", '"&E17&"',"&F17&", "&G17&");" -> INSERT INTO public.coupon (plancode, age, "year", couponrate, benefittype, benefitrate, premiumrate) VALUES('EN60', 26, 6, 8, 'A',600, 1.01); | I17: ="{""age"":"""&B17&""", ""year"":"""&C17&""", ""couponrate"":"""&D17&""", ""benefittype"":"""&E17&""", ""benefitrate"":"""&F17&""", """&G$11&""":"""&G17&"""}" -> {"age":"26", "year":"6", "couponrate":"8", "benefittype":"A", "benefitrate":"600", "premiumrate":"1.01"} | J17: =IF(OR(I18="]", I17="[", I17="]"), "", ",") -> ,
A18: ='EN60'!A$3 -> EN60 | B18: =B17 -> 26 | C18: =C17+1 -> 7 | D18: =IF(C18+B18=80,0,8) -> 8 | E18: A | F18: =IF(C18>7, 800, C18*100) -> 700 | G18: =G17 -> 1.01 | H18: ="INSERT INTO public.coupon ("&A$11&", "&B$11&", """&C$11&""", "&D$11&", "&E$11&", "&F$11&", "&G$11&") VALUES('"&A18&"', "&B18&", "&C18&", "&D18&", '"&E18&"',"&F18&", "&G18&");" -> INSERT INTO public.coupon (plancode, age, "year", couponrate, benefittype, benefitrate, premiumrate) VALUES('EN60', 26, 7, 8, 'A',700, 1.01); | I18: ="{""age"":"""&B18&""", ""year"":"""&C18&""", ""couponrate"":"""&D18&""", ""benefittype"":"""&E18&""", ""benefitrate"":"""&F18&""", """&G$11&""":"""&G18&"""}" -> {"age":"26", "year":"7", "couponrate":"8", "benefittype":"A", "benefitrate":"700", "premiumrate":"1.01"} | J18: =IF(OR(I19="]", I18="[", I18="]"), "", ",") -> ,
A19: ='EN60'!A$3 -> EN60 | B19: =B18 -> 26 | C19: =C18+1 -> 8 | D19: =IF(C19+B19=80,0,8) -> 8 | E19: A | F19: =IF(C19>7, 800, C19*100) -> 800 | G19: =G18 -> 1.01 | H19: ="INSERT INTO public.coupon ("&A$11&", "&B$11&", """&C$11&""", "&D$11&", "&E$11&", "&F$11&", "&G$11&") VALUES('"&A19&"', "&B19&", "&C19&", "&D19&", '"&E19&"',"&F19&", "&G19&");" -> INSERT INTO public.coupon (plancode, age, "year", couponrate, benefittype, benefitrate, premiumrate) VALUES('EN60', 26, 8, 8, 'A',800, 1.01); | I19: ="{""age"":"""&B19&""", ""year"":"""&C19&""", ""couponrate"":"""&D19&""", ""benefittype"":"""&E19&""", ""benefitrate"":"""&F19&""", """&G$11&""":"""&G19&"""}" -> {"age":"26", "year":"8", "couponrate":"8", "benefittype":"A", "benefitrate":"800", "premiumrate":"1.01"} | J19: =IF(OR(I20="]", I19="[", I19="]"), "", ",") -> ,
A20: ='EN60'!A$3 -> EN60 | B20: =B19 -> 26 | C20: =C19+1 -> 9 | D20: =IF(C20+B20=80,0,8) -> 8 | E20: A | F20: =IF(C20>7, 800, C20*100) -> 800 | G20: =G19 -> 1.01 | H20: ="INSERT INTO public.coupon ("&A$11&", "&B$11&", """&C$11&""", "&D$11&", "&E$11&", "&F$11&", "&G$11&") VALUES('"&A20&"', "&B20&", "&C20&", "&D20&", '"&E20&"',"&F20&", "&G20&");" -> INSERT INTO public.coupon (plancode, age, "year", couponrate, benefittype, benefitrate, premiumrate) VALUES('EN60', 26, 9, 8, 'A',800, 1.01); | I20: ="{""age"":"""&B20&""", ""year"":"""&C20&""", ""couponrate"":"""&D20&""", ""benefittype"":"""&E20&""", ""benefitrate"":"""&F20&""", """&G$11&""":"""&G20&"""}" -> {"age":"26", "year":"9", "couponrate":"8", "benefittype":"A", "benefitrate":"800", "premiumrate":"1.01"} | J20: =IF(OR(I21="]", I20="[", I20="]"), "", ",") -> ,
